Workbook

Sheet Assumptions
A1: Assumption | B1: Value | C1: Note
A2: AUD to USD rate | B2: 0.7 | C2: Applied to AUD rows. Edit B2 to refresh every sheet.
A3: USD to USD | B3: 1 | C3: No conversion.
A4: USD to IDR rate | B4: 17500 | C4: Applied to all USD Value to get Value IDR. Edit B4 to refresh every sheet.
A5: Rows with non-integer quantity | B5: Excluded | C5: 10 rows removed (SSB Unit / Orica Australia / 2026).
A6: Rows removed by instruction | B6: Excluded | C6: 8 rows 'Komatsu 830 Ultima/Westech Truck Bodies Components' (Austin, Australia, 2023) removed.
A7: Net Weight | B7: As declared | C7: Present for every row because every row was sourced from a screenshot showing a Net Weight column.
A8: Brand / Type-Model | B8: NA where not applicable | C8: Filled only when Original Goods Description clearly identifies a truck brand and model. Spare parts, tanks, trailers and generic components are marked NA rather than guessed.
A9: Customer Category | B9: Owner / Contractor / Principal / Trader-Distributor / Fabricator | C9: Verified against public industry sources (company sites, mining news, Wikipedia), not inferred from name alone.
A10: 2026 coverage | B10: Jan-Sep 2026 | C10: Partial year.

Sheet Raw Data
A1: Competitor | B1: Product Category | C1: Buyer | D1: Customer Category | E1: Country | F1: Year | G1: Quantity | H1: Unit Price | I1: Currency | J1: FX to USD | K1: Value USD | L1: Value IDR | M1: Value USD per Unit | N1: Value IDR per Unit | O1: Original Goods Description | P1: Brand | Q1: Type/Model | R1: Net Weight | S1: Weight per Unit | T1: Freight | U1: Insurance | V1: FOB | W1: Freight IDR | X1: Insurance IDR | Y1: FOB IDR
A2: Austin Engineering | B2: Dump bodies/truck trays | C2: Hamersley Iron Pty Limited | D2: Owner | E2: Australia | F2: 2026 | G2: 3 | H2: 198582.12 | I2: AUD | J2: =IF($I2="AUD",Assumptions!$B$2,Assumptions!$B$3) | K2: =$G2*$H2*$J2 | L2: =$K2*Assumptions!$B$4 | M2: =RawTx[[#This Row],[Value USD]]/RawTx[[#This Row],[Quantity]] | N2: =RawTx[[#This Row],[Value IDR]]/RawTx[[#This Row],[Quantity]] | O2: RTIO - KOMATSU 930E - 4 HPT STD (177390C) - WEST ANGELAS C/W ACCESSORIES | P2: Komatsu | Q2: 930E | R2: 100650 | S2: =IFERROR($R2/$G2,"") | T2: 34369.86 | U2: 3593.37 | V2: 850566 | W2: =IF(ISNUMBER($T2),$T2*$J2*Assumptions!$B$4,"NA") | X2: =IF(ISNUMBER($U2),$U2*$J2*Assumptions!$B$4,"NA") | Y2: =IF(ISNUMBER($V2),$V2*$J2*Assumptions!$B$4,"NA")
A3: Austin Engineering | B3: Dump bodies/truck trays | C3: Hamersley Iron Pty Limited | D3: Owner | E3: Australia | F3: 2026 | G3: 3 | H3: 202635.39 | I3: AUD | J3: =IF($I3="AUD",Assumptions!$B$2,Assumptions!$B$3) | K3: =$G3*$H3*$J3 | L3: =$K3*Assumptions!$B$4 | M3: =RawTx[[#This Row],[Value USD]]/RawTx[[#This Row],[Quantity]] | N3: =RawTx[[#This Row],[Value IDR]]/RawTx[[#This Row],[Quantity]] | O3: RTIO - KOMATSU 930E - 4 HPT STD (177390B) - WEST ANGELAS C/W ACCESSORIES | P3: Komatsu | Q3: 930E | R3: 101070 | S3: =IFERROR($R3/$G3,"") | T3: 34369.86 | U3: 3593.37 | V3: 867926.91 | W3: =IF(ISNUMBER($T3),$T3*$J3*Assumptions!$B$4,"NA") | X3: =IF(ISNUMBER($U3),$U3*$J3*Assumptions!$B$4,"NA") | Y3: =IF(ISNUMBER($V3),$V3*$J3*Assumptions!$B$4,"NA")
A4: Austin Engineering | B4: Dump bodies/truck trays | C4: Hamersley Iron Pty Limited | D4: Owner | E4: Australia | F4: 2026 | G4: 6 | H4: 197612.79 | I4: AUD | J4: =IF($I4="AUD",Assumptions!$B$2,Assumptions!$B$3) | K4: =$G4*$H4*$J4 | L4: =$K4*Assumptions!$B$4 | M4: =RawTx[[#This Row],[Value USD]]/RawTx[[#This Row],[Quantity]] | N4: =RawTx[[#This Row],[Value IDR]]/RawTx[[#This Row],[Quantity]] | O4: RTIO - KOMATSU 830E-1 HPT STD - MESA A C/W ACCESSORIES | P4: Komatsu | Q4: 830E-1 | R4: 166.52 | S4: =IFERROR($R4/$G4,"") | T4: 252851.4 | U4: 9692.64 | V4: 1685676 | W4: =IF(ISNUMBER($T4),$T4*$J4*Assumptions!$B$4,"NA") | X4: =IF(ISNUMBER($U4),$U4*$J4*Assumptions!$B$4,"NA") | Y4: =IF(ISNUMBER($V4),$V4*$J4*Assumptions!$B$4,"NA")
A5: Austin Engineering | B5: Dump bodies/truck trays | C5: Hamersley Iron Pty Limited | D5: Owner | E5: Australia | F5: 2026 | G5: 2 | H5: 199188.62 | I5: AUD | J5: =IF($I5="AUD",Assumptions!$B$2,Assumptions!$B$3) | K5: =$G5*$H5*$J5 | L5: =$K5*Assumptions!$B$4 | M5: =RawTx[[#This Row],[Value USD]]/RawTx[[#This Row],[Quantity]] | N5: =RawTx[[#This Row],[Value IDR]]/RawTx[[#This Row],[Quantity]] | O5: RTIO - KOMATSU 830E-1 HPT STD - MESA A C/W ACCESSORIES PO REFERENCE: 301... | P5: Komatsu | Q5: 830E-1 | R5: 55508 | S5: =IFERROR($R5/$G5,"") | T5: 33713.52 | U5: 3524.75 | V5: 561892 | W5: =IF(ISNUMBER($T5),$T5*$J5*Assumptions!$B$4,"NA") | X5: =IF(ISNUMBER($U5),$U5*$J5*Assumptions!$B$4,"NA") | Y5: =IF(ISNUMBER($V5),$V5*$J5*Assumptions!$B$4,"NA")
A6: Austin Engineering | B6: Dump bodies/truck trays | C6: Hamersley Iron Pty Limited | D6: Owner | E6: Australia | F6: 2026 | G6: 4 | H6: 15754.06 | I6: AUD | J6: =IF($I6="AUD",Assumptions!$B$2,Assumptions!$B$3) | K6: =$G6*$H6*$J6 | L6: =$K6*Assumptions!$B$4 | M6: =RawTx[[#This Row],[Value USD]]/RawTx[[#This Row],[Quantity]] | N6: =RawTx[[#This Row],[Value IDR]]/RawTx[[#This Row],[Quantity]] | O6: KOMATSU HD785 - 7 ULTIMA - 178320B C/W ACCESSORIES | P6: Komatsu | Q6: HD785-7 | R6: 62320 | S6: =IFERROR($R6/$G6,"") | T6: NA | U6: NA | V6: NA | W6: =IF(ISNUMBER($T6),$T6*$J6*Assumptions!$B$4,"NA") | X6: =IF(ISNUMBER($U6),$U6*$J6*Assumptions!$B$4,"NA") | Y6: =IF(ISNUMBER($V6),$V6*$J6*Assumptions!$B$4,"NA")
A7: Austin Engineering | B7: Dump bodies/truck trays | C7: Hamersley Iron Pty Limited | D7: Owner | E7: Australia | F7: 2026 | G7: 4 | H7: 199188.62 | I7: AUD | J7: =IF($I7="AUD",Assumptions!$B$2,Assumptions!$B$3) | K7: =$G7*$H7*$J7 | L7: =$K7*Assumptions!$B$4 | M7: =RawTx[[#This Row],[Value USD]]/RawTx[[#This Row],[Quantity]] | N7: =RawTx[[#This Row],[Value IDR]]/RawTx[[#This Row],[Quantity]] | O7: RTIO - KOMATSU 830E-1 HPT STD-HOPE DOWNS 4 C/W ACCESSORIES PO REFEREN... | P7: Komatsu | Q7: 830E-1 | R7: 111016 | S7: =IFERROR($R7/$G7,"") | T7: 33713.52 | U7: 3524.75 | V7: 1123784 | W7: =IF(ISNUMBER($T7),$T7*$J7*Assumptions!$B$4,"NA") | X7: =IF(ISNUMBER($U7),$U7*$J7*Assumptions!$B$4,"NA") | Y7: =IF(ISNUMBER($V7),$V7*$J7*Assumptions!$B$4,"NA")
A8: Austin Engineering | B8: Dump bodies/truck trays | C8: Hamersley Iron Pty Limited | D8: Owner | E8: Australia | F8: 2026 | G8: 3 | H8: 202812.21 | I8: AUD | J8: =IF($I8="AUD",Assumptions!$B$2,Assumptions!$B$3) | K8: =$G8*$H8*$J8 | L8: =$K8*Assumptions!$B$4 | M8: =RawTx[[#This Row],[Value USD]]/RawTx[[#This Row],[Quantity]] | N8: =RawTx[[#This Row],[Value IDR]]/RawTx[[#This Row],[Quantity]] | O8: RTIO - KOM 830E-1 HPT STD - BROCKMAN 4 C/W ACCESSORIES | P8: Komatsu | Q8: 830E-1 | R8: 83262 | S8: =IFERROR($R8/$G8,"") | T8: 255209.24 | U8: 9783.02 | V8: 842838 | W8: =IF(ISNUMBER($T8),$T8*$J8*Assumptions!$B$4,"NA") | X8: =IF(ISNUMBER($U8),$U8*$J8*Assumptions!$B$4,"NA") | Y8: =IF(ISNUMBER($V8),$V8*$J8*Assumptions!$B$4,"NA")
A9: Austin Engineering | B9: Dump bodies/truck trays | C9: Hamersley Iron Pty Limited | D9: Owner | E9: Australia | F9: 2026 | G9: 3 | H9: 202812.21 | I9: AUD | J9: =IF($I9="AUD",Assumptions!$B$2,Assumptions!$B$3) | K9: =$G9*$H9*$J9 | L9: =$K9*Assumptions!$B$4 | M9: =RawTx[[#This Row],[Value USD]]/RawTx[[#This Row],[Quantity]] | N9: =RawTx[[#This Row],[Value IDR]]/RawTx[[#This Row],[Quantity]] | O9: RTIO - KOM 830E-1 HPT STD - HOPE DOWN 1 C/W ACCESSORIES | P9: Komatsu | Q9: 830E-1 | R9: 83262 | S9: =IFERROR($R9/$G9,"") | T9: 252851.4 | U9: 9692.64 | V9: 842838 | W9: =IF(ISNUMBER($T9),$T9*$J9*Assumptions!$B$4,"NA") | X9: =IF(ISNUMBER($U9),$U9*$J9*Assumptions!$B$4,"NA") | Y9: =IF(ISNUMBER($V9),$V9*$J9*Assumptions!$B$4,"NA")
A10: Austin Engineering | B10: Dump bodies/truck trays | C10: Hamersley Iron Pty Limited | D10: Owner | E10: Australia | F10: 2026 | G10: 6 | H10: 204671.84 | I10: AUD | J10: =IF($I10="AUD",Assumptions!$B$2,Assumptions!$B$3) | K10: =$G10*$H10*$J10 | L10: =$K10*Assumptions!$B$4 | M10: =RawTx[[#This Row],[Value USD]]/RawTx[[#This Row],[Quantity]] | N10: =RawTx[[#This Row],[Value IDR]]/RawTx[[#This Row],[Quantity]] | O10: RTIO - KOM 830E-1 HPT STD - BROCKMAN 4 C/W ACCESSORIES PO REFERENCE : 3... | P10: Komatsu | Q10: 830E-1 | R10: 166524 | S10: =IFERROR($R10/$G10,"") | T10: 33713.52 | U10: 3524.75 | V10: 1685676 | W10: =IF(ISNUMBER($T10),$T10*$J10*Assumptions!$B$4,"NA") | X10: =IF(ISNUMBER($U10),$U10*$J10*Assumptions!$B$4,"NA") | Y10: =IF(ISNUMBER($V10),$V10*$J10*Assumptions!$B$4,"NA")
A11: Austin Engineering | B11: Dump bodies/truck trays | C11: Hamersley Iron Pty Limited | D11: Owner | E11: Australia | F11: 2026 | G11: 1 | H11: 200814.39 | I11: AUD | J11: =IF($I11="AUD",Assumptions!$B$2,Assumptions!$B$3) | K11: =$G11*$H11*$J11 | L11: =$K11*Assumptions!$B$4 | M11: =RawTx[[#This Row],[Value USD]]/RawTx[[#This Row],[Quantity]] | N11: =RawTx[[#This Row],[Value IDR]]/RawTx[[#This Row],[Quantity]] | O11: RTIO-KOM 830E-5 HPT STD-BROCKMAN 4 C/W ACCESSORIES | P11: Komatsu | Q11: 830E-5 | R11: 28425 | S11: =IFERROR($R11/$G11,"") | T11: 255209.24 | U11: 9783.02 | V11: 284859 | W11: =IF(ISNUMBER($T11),$T11*$J11*Assumptions!$B$4,"NA") | X11: =IF(ISNUMBER($U11),$U11*$J11*Assumptions!$B$4,"NA") | Y11: =IF(ISNUMBER($V11),$V11*$J11*Assumptions!$B$4,"NA")
A12: Austin Engineering | B12: Dump bodies/truck trays | C12: Hamersley Iron Pty Limited | D12: Owner | E12: Australia | F12: 2026 | G12: 3 | H12: 198055.88 | I12: AUD | J12: =IF($I12="AUD",Assumptions!$B$2,Assumptions!$B$3) | K12: =$G12*$H12*$J12 | L12: =$K12*Assumptions!$B$4 | M12: =RawTx[[#This Row],[Value USD]]/RawTx[[#This Row],[Quantity]] | N12: =RawTx[[#This Row],[Value IDR]]/RawTx[[#This Row],[Quantity]] | O12: RTIO-KOM 830E-1 HPT STD - BROCKMAN 4 C/W ACCESSORIES | P12: Komatsu | Q12: 830E-1 | R12: 83262 | S12: =IFERROR($R12/$G12,"") | T12: 252851.4 | U12: 9692.64 | V12: 842838 | W12: =IF(ISNUMBER($T12),$T12*$J12*Assumptions!$B$4,"NA") | X12: =IF(ISNUMBER($U12),$U12*$J12*Assumptions!$B$4,"NA") | Y12: =IF(ISNUMBER($V12),$V12*$J12*Assumptions!$B$4,"NA")
A13: Austin Engineering | B13: Dump bodies/truck trays | C13: Hamersley Iron Pty Limited | D13: Owner | E13: Australia | F13: 2026 | G13: 2 | H13: 202217.24 | I13: AUD | J13: =IF($I13="AUD",Assumptions!$B$2,Assumptions!$B$3) | K13: =$G13*$H13*$J13 | L13: =$K13*Assumptions!$B$4 | M13: =RawTx[[#This Row],[Value USD]]/RawTx[[#This Row],[Quantity]] | N13: =RawTx[[#This Row],[Value IDR]]/RawTx[[#This Row],[Quantity]] | O13: RTIO-KOM 830E-5 HPT STD (177394B) HOPE DOWNS 1 EXP C/W ACCESSORIES | P13: Komatsu | Q13: 830E-5 | R13: 56850 | S13: =IFERROR($R13/$G13,"") | T13: 255209.24 | U13: 9783.02 | V13: 573697.94 | W13: =IF(ISNUMBER($T13),$T13*$J13*Assumptions!$B$4,"NA") | X13: =IF(ISNUMBER($U13),$U13*$J13*Assumptions!$B$4,"NA") | Y13: =IF(ISNUMBER($V13),$V13*$J13*Assumptions!$B$4,"NA")
A14: Austin Engineering | B14: Dump bodies/truck trays | C14: Hamersley Iron Pty Limited | D14: Owner | E14: Australia | F14: 2026 | G14: 3 | H14: 204037.44 | I14: AUD | J14: =IF($I14="AUD",Assumptions!$B$2,Assumptions!$B$3) | K14: =$G14*$H14*$J14 | L14: =$K14*Assumptions!$B$4 | M14: =RawTx[[#This Row],[Value USD]]/RawTx[[#This Row],[Quantity]] | N14: =RawTx[[#This Row],[Value IDR]]/RawTx[[#This Row],[Quantity]] | O14: RTIO-KOM 830E-5 HPT STD (177394B) HOPE DOWNS 1 EXP C/W ACCESSORIES PO R... | P14: Komatsu | Q14: 830E-5 | R14: 85275 | S14: =IFERROR($R14/$G14,"") | T14: 34421.88 | U14: 3598.81 | V14: 860546.91 | W14: =IF(ISNUMBER($T14),$T14*$J14*Assumptions!$B$4,"NA") | X14: =IF(ISNUMBER($U14),$U14*$J14*Assumptions!$B$4,"NA") | Y14: =IF(ISNUMBER($V14),$V14*$J14*Assumptions!$B$4,"NA")
A15: Austin Engineering | B15: Dump bodies/truck trays | C15: Hamersley Iron Pty Limited | D15: Owner | E15: Australia | F15: 2026 | G15: 1 | H15: 204037.44 | I15: AUD | J15: =IF($I15="AUD",Assumptions!$B$2,Assumptions!$B$3) | K15: =$G15*$H15*$J15 | L15: =$K15*Assumptions!$B$4 | M15: =RawTx[[#This Row],[Value USD]]/RawTx[[#This Row],[Quantity]] | N15: =RawTx[[#This Row],[Value IDR]]/RawTx[[#This Row],[Quantity]] | O15: RTIO-KOM 830E-AC HPT HD (177394B) HOPE DOWNS 4 C/W ACCESSORIES PO REFE... | P15: Komatsu | Q15: 830E-AC | R15: 28425 | S15: =IFERROR($R15/$G15,"") | T15: 34421.88 | U15: 3598.81 | V15: 286848.97 | W15: =IF(ISNUMBER($T15),$T15*$J15*Assumptions!$B$4,"NA") | X15: =IF(ISNUMBER($U15),$U15*$J15*Assumptions!$B$4,"NA") | Y15: =IF(ISNUMBER($V15),$V15*$J15*Assumptions!$B$4,"NA")
A16: Austin Engineering | B16: Dump bodies/truck trays | C16: Hamersley Iron Pty Limited | D16: Owner | E16: Australia | F16: 2026 | G16: 2 | H16: 204037.44 | I16: AUD | J16: =IF($I16="AUD",Assumptions!$B$2,Assumptions!$B$3) | K16: =$G16*$H16*$J16 | L16: =$K16*Assumptions!$B$4 | M16: =RawTx[[#This Row],[Value USD]]/RawTx[[#This Row],[Quantity]] | N16: =RawTx[[#This Row],[Value IDR]]/RawTx[[#This Row],[Quantity]] | O16: RTIO-KOM 830E-5 HPT STD (177394B) HOPE DOWNS 2 EXP C/W ACCESSORIES PO F... | P16: Komatsu | Q16: 830E-5 | R16: 56850 | S16: =IFERROR($R16/$G16,"") | T16: 34421.88 | U16: 3598.81 | V16: 573697.94 | W16: =IF(ISNUMBER($T16),$T16*$J16*Assumptions!$B$4,"NA") | X16: =IF(ISNUMBER($U16),$U16*$J16*Assumptions!$B$4,"NA") | Y16: =IF(ISNUMBER($V16),$V16*$J16*Assumptions!$B$4,"NA")
A17: Austin Engineering | B17: Dump bodies/truck trays | C17: Hamersley Iron Pty Limited | D17: Owner | E17: Australia | F17: 2026 | G17: 5 | H17: 200574.22 | I17: AUD | J17: =IF($I17="AUD",Assumptions!$B$2,Assumptions!$B$3) | K17: =$G17*$H17*$J17 | L17: =$K17*Assumptions!$B$4 | M17: =RawTx[[#This Row],[Value USD]]/RawTx[[#This Row],[Quantity]] | N17: =RawTx[[#This Row],[Value IDR]]/RawTx[[#This Row],[Quantity]] | O17: RTIO-KOM 830E-5 HPT STD (177394B) HOPE DOWNS 2 EXP C/W ACCESSORIES | P17: Komatsu | Q17: 830E-5 | R17: 142125 | S17: =IFERROR($R17/$G17,"") | T17: 258164.07 | U17: 9896.29 | V17: 1434244.9 | W17: =IF(ISNUMBER($T17),$T17*$J17*Assumptions!$B$4,"NA") | X17: =IF(ISNUMBER($U17),$U17*$J17*Assumptions!$B$4,"NA") | Y17: =IF(ISNUMBER($V17),$V17*$J17*Assumptions!$B$4,"NA")
A18: Austin Engineering | B18: Dump bodies/truck trays | C18: Hamersley Iron Pty Limited | D18: Owner | E18: Australia | F18: 2026 | G18: 1 | H18: 200574.22 | I18: AUD | J18: =IF($I18="AUD",Assumptions!$B$2,Assumptions!$B$3) | K18: =$G18*$H18*$J18 | L18: =$K18*Assumptions!$B$4 | M18: =RawTx[[#This Row],[Value USD]]/RawTx[[#This Row],[Quantity]] | N18: =RawTx[[#This Row],[Value IDR]]/RawTx[[#This Row],[Quantity]] | O18: RTIO-KOM 830E-5 HPT STD (177394B) HOPE DOWNS 1 EXP C/W ACCESSORIES | P18: Komatsu | Q18: 830E-5 | R18: 28425 | S18: =IFERROR($R18/$G18,"") | T18: 258164.07 | U18: 9896.29 | V18: 286848.97 | W18: =IF(ISNUMBER($T18),$T18*$J18*Assumptions!$B$4,"NA") | X18: =IF(ISNUMBER($U18),$U18*$J18*Assumptions!$B$4,"NA") | Y18: =IF(ISNUMBER($V18),$V18*$J18*Assumptions!$B$4,"NA")
... A21: Austin Engineering | B21: Dump bodies/truck trays | C21: Hamersley Iron Pty Limited | D21: Owner | E21: Australia | F21: 2026 | G21: 6 | H21: 202540.96 | I21: AUD | J21: =IF($I21="AUD",Assumptions!$B$2,Assumptions!$B$3) | K21: =$G21*$H21*$J21 | L21: =$K21*Assumptions!$B$4 | M21: =RawTx[[#This Row],[Value USD]]/RawTx[[#This Row],[Quantity]] | N21: =RawTx[[#This Row],[Value IDR]]/RawTx[[#This Row],[Quantity]] | O21: RIO-TINTO - KOMATSU 830E-5 HPT STD (177394B) - BROCKMAN 4 C/W ACCESSORI... | P21: Komatsu | Q21: 830E-5 | R21: 170550 | S21: =IFERROR($R21/$G21,"") | T21: 258164.07 | U21: 9896.29 | V21: 1721093.8 | W21: =IF(ISNUMBER($T21),$T21*$J21*Assumptions!$B$4,"NA") | X21: =IF(ISNUMBER($U21),$U21*$J21*Assumptions!$B$4,"NA") | Y21: =IF(ISNUMBER($V21),$V21*$J21*Assumptions!$B$4,"NA")
A22: Austin Engineering | B22: Dump bodies/truck trays | C22: Hamersley Iron Pty Limited | D22: Owner | E22: Australia | F22: 2026 | G22: 2 | H22: 192116.14 | I22: AUD | J22: =IF($I22="AUD",Assumptions!$B$2,Assumptions!$B$3) | K22: =$G22*$H22*$J22 | L22: =$K22*Assumptions!$B$4 | M22: =RawTx[[#This Row],[Value USD]]/RawTx[[#This Row],[Quantity]] | N22: =RawTx[[#This Row],[Value IDR]]/RawTx[[#This Row],[Quantity]] | O22: RIO-TINTO - KOMATSU 830E-1 HPT STD (177394B) - BROCKMAN 4 C/W ACCESSORI... | P22: Komatsu | Q22: 830E-1 | R22: 56850 | S22: =IFERROR($R22/$G22,"") | T22: NA | U22: NA | V22: NA | W22: =IF(ISNUMBER($T22),$T22*$J22*Assumptions!$B$4,"NA") | X22: =IF(ISNUMBER($U22),$U22*$J22*Assumptions!$B$4,"NA") | Y22: =IF(ISNUMBER($V22),$V22*$J22*Assumptions!$B$4,"NA")
A23: Austin Engineering | B23: Dump bodies/truck trays | C23: Hamersley Iron Pty Limited | D23: Owner | E23: Australia | F23: 2026 | G23: 4 | H23: 192116.14 | I23: AUD | J23: =IF($I23="AUD",Assumptions!$B$2,Assumptions!$B$3) | K23: =$G23*$H23*$J23 | L23: =$K23*Assumptions!$B$4 | M23: =RawTx[[#This Row],[Value USD]]/RawTx[[#This Row],[Quantity]] | N23: =RawTx[[#This Row],[Value IDR]]/RawTx[[#This Row],[Quantity]] | O23: RIO-TINTO - KOMATSU 830E-1 HPT STD (177394B) - BROCKMAN 4 C/W ACCESSORI... | P23: Komatsu | Q23: 830E-1 | R23: 113700 | S23: =IFERROR($R23/$G23,"") | T23: 34421.88 | U23: 3598.81 | V23: 1147395.9 | W23: =IF(ISNUMBER($T23),$T23*$J23*Assumptions!$B$4,"NA") | X23: =IF(ISNUMBER($U23),$U23*$J23*Assumptions!$B$4,"NA") | Y23: =IF(ISNUMBER($V23),$V23*$J23*Assumptions!$B$4,"NA")
A24: Austin Engineering | B24: Dump bodies/truck trays | C24: Hamersley Iron Pty Limited | D24: Owner | E24: Australia | F24: 2026 | G24: 3 | H24: 210082 | I24: AUD | J24: =IF($I24="AUD",Assumptions!$B$2,Assumptions!$B$3) | K24: =$G24*$H24*$J24 | L24: =$K24*Assumptions!$B$4 | M24: =RawTx[[#This Row],[Value USD]]/RawTx[[#This Row],[Quantity]] | N24: =RawTx[[#This Row],[Value IDR]]/RawTx[[#This Row],[Quantity]] | O24: RIO-TINTO-KOMATSU 830E-5HPT STD (177086C) WESTERN RANGES C/W ACCESSO... | P24: Komatsu | Q24: 830E-5 | R24: 94500 | S24: =IFERROR($R24/$G24,"") | T24: 36648.54 | U24: 3831.6 | V24: 964499.91 | W24: =IF(ISNUMBER($T24),$T24*$J24*Assumptions!$B$4,"NA") | X24: =IF(ISNUMBER($U24),$U24*$J24*Assumptions!$B$4,"NA") | Y24: =IF(ISNUMBER($V24),$V24*$J24*Assumptions!$B$4,"NA")
A25: Austin Engineering | B25: Dump bodies/truck trays | C25: Hamersley Iron Pty Limited | D25: Owner | E25: Australia | F25: 2026 | G25: 3 | H25: 189047 | I25: AUD | J25: =IF($I25="AUD",Assumptions!$B$2,Assumptions!$B$3) | K25: =$G25*$H25*$J25 | L25: =$K25*Assumptions!$B$4 | M25: =RawTx[[#This Row],[Value USD]]/RawTx[[#This Row],[Quantity]] | N25: =RawTx[[#This Row],[Value IDR]]/RawTx[[#This Row],[Quantity]] | O25: RIO-TINTO-KOMATSU 930E-4HPT STD (177390B) WEST ANGELAS C/W ACCESSORIE... | P25: Komatsu | Q25: 930E-4 | R25: 101070 | S25: =IFERROR($R25/$G25,"") | T25: 36648.54 | U25: 3831.6 | V25: 867926.91 | W25: =IF(ISNUMBER($T25),$T25*$J25*Assumptions!$B$4,"NA") | X25: =IF(ISNUMBER($U25),$U25*$J25*Assumptions!$B$4,"NA") | Y25: =IF(ISNUMBER($V25),$V25*$J25*Assumptions!$B$4,"NA")
A26: Austin Engineering | B26: Dump bodies/truck trays | C26: Hamersley Iron Pty Limited | D26: Owner | E26: Australia | F26: 2026 | G26: 4 | H26: 188249.86 | I26: AUD | J26: =IF($I26="AUD",Assumptions!$B$2,Assumptions!$B$3) | K26: =$G26*$H26*$J26 | L26: =$K26*Assumptions!$B$4 | M26: =RawTx[[#This Row],[Value USD]]/RawTx[[#This Row],[Quantity]] | N26: =RawTx[[#This Row],[Value IDR]]/RawTx[[#This Row],[Quantity]] | O26: KOMATSU 830E-5HPT STD (177390B) HOPE DOWNS 2 EXP C/W ACCESSORIES PO RI... | P26: Komatsu | Q26: 830E-5 | R26: 113700 | S26: =IFERROR($R26/$G26,"") | T26: 34520.28 | U26: 3609.09 | V26: 1147395.9 | W26: =IF(ISNUMBER($T26),$T26*$J26*Assumptions!$B$4,"NA") | X26: =IF(ISNUMBER($U26),$U26*$J26*Assumptions!$B$4,"NA") | Y26: =IF(ISNUMBER($V26),$V26*$J26*Assumptions!$B$4,"NA")
A27: Austin Engineering | B27: Dump bodies/truck trays | C27: Hamersley Iron Pty Limited | D27: Owner | E27: Australia | F27: 2026 | G27: 1 | H27: 189864.27 | I27: AUD | J27: =IF($I27="AUD",Assumptions!$B$2,Assumptions!$B$3) | K27: =$G27*$H27*$J27 | L27: =$K27*Assumptions!$B$4 | M27: =RawTx[[#This Row],[Value USD]]/RawTx[[#This Row],[Quantity]] | N27: =RawTx[[#This Row],[Value IDR]]/RawTx[[#This Row],[Quantity]] | O27: KOMATSU 930E-4HPT STDI (177390B) WEST ANGELAS C/W ACCESSORIES PO REFF:... | P27: Komatsu | Q27: 930E-4 | R27: 34295 | S27: =IFERROR($R27/$G27,"") | T27: 34520.28 | U27: 3609.09 | V27: 289308.97 | W27: =IF(ISNUMBER($T27),$T27*$J27*Assumptions!$B$4,"NA") | X27: =IF(ISNUMBER($U27),$U27*$J27*Assumptions!$B$4,"NA") | Y27: =IF(ISNUMBER($V27),$V27*$J27*Assumptions!$B$4,"NA")
A28: Austin Engineering | B28: Dump bodies/truck trays | C28: Hamersley Iron Pty Limited | D28: Owner | E28: Australia | F28: 2026 | G28: 1 | H28: 189864.27 | I28: AUD | J28: =IF($I28="AUD",Assumptions!$B$2,Assumptions!$B$3) | K28: =$G28*$H28*$J28 | L28: =$K28*Assumptions!$B$4 | M28: =RawTx[[#This Row],[Value USD]]/RawTx[[#This Row],[Quantity]] | N28: =RawTx[[#This Row],[Value IDR]]/RawTx[[#This Row],[Quantity]] | O28: KOMATSU 930E-4HPT STD-NAMMULDI (177390B) C/W ACCESSORIES PO REFF:3016... | P28: Komatsu | Q28: 930E-4 | R28: 34295 | S28: =IFERROR($R28/$G28,"") | T28: 34520.28 | U28: 3609.09 | V28: 289308.97 | W28: =IF(ISNUMBER($T28),$T28*$J28*Assumptions!$B$4,"NA") | X28: =IF(ISNUMBER($U28),$U28*$J28*Assumptions!$B$4,"NA") | Y28: =IF(ISNUMBER($V28),$V28*$J28*Assumptions!$B$4,"NA")
A29: Austin Engineering | B29: Dump bodies/truck trays | C29: Hamersley Iron Pty Limited | D29: Owner | E29: Australia | F29: 2026 | G29: 6 | H29: 188037.05 | I29: AUD | J29: =IF($I29="AUD",Assumptions!$B$2,Assumptions!$B$3) | K29: =$G29*$H29*$J29 | L29: =$K29*Assumptions!$B$4 | M29: =RawTx[[#This Row],[Value USD]]/RawTx[[#This Row],[Quantity]] | N29: =RawTx[[#This Row],[Value IDR]]/RawTx[[#This Row],[Quantity]] | O29: NAMMULDI-930E-4 HPT STD (177390B) C/W ACCESSORIES PO REFERENCE : 30161... | P29: Komatsu | Q29: 930E-4 | R29: 205770 | S29: =IFERROR($R29/$G29,"") | T29: 90090.81 | U29: 3743.19 | V29: 1735853.8 | W29: =IF(ISNUMBER($T29),$T29*$J29*Assumptions!$B$4,"NA") | X29: =IF(ISNUMBER($U29),$U29*$J29*Assumptions!$B$4,"NA") | Y29: =IF(ISNUMBER($V29),$V29*$J29*Assumptions!$B$4,"NA")
A30: Austin Engineering | B30: Dump bodies/truck trays | C30: Anglo Coal Capcoal Management | D30: Owner | E30: Australia | F30: 2025 | G30: 6 | H30: 285631.12 | I30: AUD | J30: =IF($I30="AUD",Assumptions!$B$2,Assumptions!$B$3) | K30: =$G30*$H30*$J30 | L30: =$K30*Assumptions!$B$4 | M30: =RawTx[[#This Row],[Value USD]]/RawTx[[#This Row],[Quantity]] | N30: =RawTx[[#This Row],[Value IDR]]/RawTx[[#This Row],[Quantity]] | O30: KOMATSU 830E-5 HPT TRUCK BODY C/W ACCESSORIES, PO REFERENCE : 4503710... | P30: Komatsu | Q30: 830E-5 | R30: 212100 | S30: =IFERROR($R30/$G30,"") | T30: 52711.74 | U30: 5511.01 | V30: 2635587 | W30: =IF(ISNUMBER($T30),$T30*$J30*Assumptions!$B$4,"NA") | X30: =IF(ISNUMBER($U30),$U30*$J30*Assumptions!$B$4,"NA") | Y30: =IF(ISNUMBER($V30),$V30*$J30*Assumptions!$B$4,"NA")
A31: Austin Engineering | B31: Dump bodies/truck trays | C31: Hamersley Iron Pty Limited | D31: Owner | E31: Australia | F31: 2025 | G31: 2 | H31: 192512.54 | I31: AUD | J31: =IF($I31="AUD",Assumptions!$B$2,Assumptions!$B$3) | K31: =$G31*$H31*$J31 | L31: =$K31*Assumptions!$B$4 | M31: =RawTx[[#This Row],[Value USD]]/RawTx[[#This Row],[Quantity]] | N31: =RawTx[[#This Row],[Value IDR]]/RawTx[[#This Row],[Quantity]] | O31: TOM PRICE-830E-AC HPT HD (177392B) C/W ACCESSORIESPO REFERENCE : 30161... | P31: Komatsu | Q31: 830E-AC | R31: 60836 | S31: =IFERROR($R31/$G31,"") | T31: 34672.84 | U31: 3625.05 | V31: 586245.94 | W31: =IF(ISNUMBER($T31),$T31*$J31*Assumptions!$B$4,"NA") | X31: =IF(ISNUMBER($U31),$U31*$J31*Assumptions!$B$4,"NA") | Y31: =IF(ISNUMBER($V31),$V31*$J31*Assumptions!$B$4,"NA")
A32: Austin Engineering | B32: Dump bodies/truck trays | C32: Hamersley Iron Pty Limited | D32: Owner | E32: Australia | F32: 2025 | G32: 2 | H32: 191013.07 | I32: AUD | J32: =IF($I32="AUD",Assumptions!$B$2,Assumptions!$B$3) | K32: =$G32*$H32*$J32 | L32: =$K32*Assumptions!$B$4 | M32: =RawTx[[#This Row],[Value USD]]/RawTx[[#This Row],[Quantity]] | N32: =RawTx[[#This Row],[Value IDR]]/RawTx[[#This Row],[Quantity]] | O32: TOM PRICE-830E-AC HPT HD (177392B) C/W ACCESSORIESPO REFERENCE : 30161... | P32: Komatsu | Q32: 830E-AC | R32: 60836 | S32: =IFERROR($R32/$G32,"") | T32: 28935.86 | U32: 3025.24 | V32: 586245.94 | W32: =IF(ISNUMBER($T32),$T32*$J32*Assumptions!$B$4,"NA") | X32: =IF(ISNUMBER($U32),$U32*$J32*Assumptions!$B$4,"NA") | Y32: =IF(ISNUMBER($V32),$V32*$J32*Assumptions!$B$4,"NA")
A33: Austin Engineering | B33: Dump bodies/truck trays | C33: Hamersley Iron Pty Limited | D33: Owner | E33: Australia | F33: 2025 | G33: 2 | H33: 186924.63 | I33: AUD | J33: =IF($I33="AUD",Assumptions!$B$2,Assumptions!$B$3) | K33: =$G33*$H33*$J33 | L33: =$K33*Assumptions!$B$4 | M33: =RawTx[[#This Row],[Value USD]]/RawTx[[#This Row],[Quantity]] | N33: =RawTx[[#This Row],[Value IDR]]/RawTx[[#This Row],[Quantity]] | O33: HOPE DOWNS 4-830E-AC HPT STD C/W ACCESSORIESPO REFERENCE : 3016401784 | P33: Komatsu | Q33: 830E-AC | R33: 55508 | S33: =IFERROR($R33/$G33,"") | T33: 28935.86 | U33: 3025.24 | V33: 573697.94 | W33: =IF(ISNUMBER($T33),$T33*$J33*Assumptions!$B$4,"NA") | X33: =IF(ISNUMBER($U33),$U33*$J33*Assumptions!$B$4,"NA") | Y33: =IF(ISNUMBER($V33),$V33*$J33*Assumptions!$B$4,"NA")
A34: Austin Engineering | B34: Dump bodies/truck trays | C34: Hamersley Iron Pty Limited | D34: Owner | E34: Australia | F34: 2025 | G34: 1 | H34: 186924.63 | I34: AUD | J34: =IF($I34="AUD",Assumptions!$B$2,Assumptions!$B$3) | K34: =$G34*$H34*$J34 | L34: =$K34*Assumptions!$B$4 | M34: =RawTx[[#This Row],[Value USD]]/RawTx[[#This Row],[Quantity]] | N34: =RawTx[[#This Row],[Value IDR]]/RawTx[[#This Row],[Quantity]] | O34: BROCKMAN 4-830E-5 HPT STD C/W ACCESSORIESPO REFERENCE: 3016405287 | P34: Komatsu | Q34: 830E-5 | R34: 28425 | S34: =IFERROR($R34/$G34,"") | T34: 28935.86 | U34: 3025.24 | V34: 286848.97 | W34: =IF(ISNUMBER($T34),$T34*$J34*Assumptions!$B$4,"NA") | X34: =IF(ISNUMBER($U34),$U34*$J34*Assumptions!$B$4,"NA") | Y34: =IF(ISNUMBER($V34),$V34*$J34*Assumptions!$B$4,"NA")
A35: Austin Engineering | B35: Dump bodies/truck trays | C35: Hamersley Iron Pty Limited | D35: Owner | E35: Australia | F35: 2025 | G35: 3 | H35: 193217.01 | I35: AUD | J35: =IF($I35="AUD",Assumptions!$B$2,Assumptions!$B$3) | K35: =$G35*$H35*$J35 | L35: =$K35*Assumptions!$B$4 | M35: =RawTx[[#This Row],[Value USD]]/RawTx[[#This Row],[Quantity]] | N35: =RawTx[[#This Row],[Value IDR]]/RawTx[[#This Row],[Quantity]] | O35: 830E-5 HPT MAX XHD (177086) - WESTERN RANGES C/W ACCESSORIES PO REFERE... | P35: Komatsu | Q35: 830E-5 | R35: 104166 | S35: =IFERROR($R35/$G35,"") | T35: NA | U35: NA | V35: NA | W35: =IF(ISNUMBER($T35),$T35*$J35*Assumptions!$B$4,"NA") | X35: =IF(ISNUMBER($U35),$U35*$J35*Assumptions!$B$4,"NA") | Y35: =IF(ISNUMBER($V35),$V35*$J35*Assumptions!$B$4,"NA")
A36: Austin Engineering | B36: Dump bodies/truck trays | C36: Hamersley Iron Pty Limited | D36: Owner | E36: Australia | F36: 2025 | G36: 1 | H36: 183085.26 | I36: AUD | J36: =IF($I36="AUD",Assumptions!$B$2,Assumptions!$B$3) | K36: =$G36*$H36*$J36 | L36: =$K36*Assumptions!$B$4 | M36: =RawTx[[#This Row],[Value USD]]/RawTx[[#This Row],[Quantity]] | N36: =RawTx[[#This Row],[Value IDR]]/RawTx[[#This Row],[Quantity]] | O36: 793F HPT MAX STD, MARANDOO C/W ACCESSORIES PO REFERENCE : 3014850234 | P36: Caterpillar | Q36: 793F | R36: 27890 | S36: =IFERROR($R36/$G36,"") | T36: NA | U36: NA | V36: NA | W36: =IF(ISNUMBER($T36),$T36*$J36*Assumptions!$B$4,"NA") | X36: =IF(ISNUMBER($U36),$U36*$J36*Assumptions!$B$4,"NA") | Y36: =IF(ISNUMBER($V36),$V36*$J36*Assumptions!$B$4,"NA")
A37: Austin Engineering | B37: Dump bodies/truck trays | C37: Hamersley Iron Pty Limited | D37: Owner | E37: Australia | F37: 2025 | G37: 3 | H37: 195779.35 | I37: AUD | J37: =IF($I37="AUD",Assumptions!$B$2,Assumptions!$B$3) | K37: =$G37*$H37*$J37 | L37: =$K37*Assumptions!$B$4 | M37: =RawTx[[#This Row],[Value USD]]/RawTx[[#This Row],[Quantity]] | N37: =RawTx[[#This Row],[Value IDR]]/RawTx[[#This Row],[Quantity]] | O37: 830E-5 HPT MAX XHD (177086) - WESTERN RANGES C/W ACCESSORIES PO REFERE... | P37: Komatsu | Q37: 830E-5 | R37: 104166 | S37: =IFERROR($R37/$G37,"") | T37: NA | U37: NA | V37: NA | W37: =IF(ISNUMBER($T37),$T37*$J37*Assumptions!$B$4,"NA") | X37: =IF(ISNUMBER($U37),$U37*$J37*Assumptions!$B$4,"NA") | Y37: =IF(ISNUMBER($V37),$V37*$J37*Assumptions!$B$4,"NA")
A38: Austin Engineering | B38: Dump bodies/truck trays | C38: Hamersley Iron Pty Limited | D38: Owner | E38: Australia | F38: 2025 | G38: 7 | H38: 183187.1 | I38: AUD | J38: =IF($I38="AUD",Assumptions!$B$2,Assumptions!$B$3) | K38: =$G38*$H38*$J38 | L38: =$K38*Assumptions!$B$4 | M38: =RawTx[[#This Row],[Value USD]]/RawTx[[#This Row],[Quantity]] | N38: =RawTx[[#This Row],[Value IDR]]/RawTx[[#This Row],[Quantity]] | O38: 930E HPT MAX STD, WEST ANGELAS CW/ ACCESSORIES PO REFERENCE : 30149561... | P38: Komatsu | Q38: 930E | R38: 224847 | S38: =IFERROR($R38/$G38,"") | T38: NA | U38: NA | V38: NA | W38: =IF(ISNUMBER($T38),$T38*$J38*Assumptions!$B$4,"NA") | X38: =IF(ISNUMBER($U38),$U38*$J38*Assumptions!$B$4,"NA") | Y38: =IF(ISNUMBER($V38),$V38*$J38*Assumptions!$B$4,"NA")
A39: Austin Engineering | B39: Dump bodies/truck trays | C39: Hamersley Iron Pty Limited | D39: Owner | E39: Australia | F39: 2025 | G39: 1 | H39: 183187.1 | I39: AUD | J39: =IF($I39="AUD",Assumptions!$B$2,Assumptions!$B$3) | K39: =$G39*$H39*$J39 | L39: =$K39*Assumptions!$B$4 | M39: =RawTx[[#This Row],[Value USD]]/RawTx[[#This Row],[Quantity]] | N39: =RawTx[[#This Row],[Value IDR]]/RawTx[[#This Row],[Quantity]] | O39: 930E HPT MAX STD, WEST ANGELAS CW/ ACCESSORIES PO REFERENCE : 30149561... | P39: Komatsu | Q39: 930E | R39: 34489 | S39: =IFERROR($R39/$G39,"") | T39: NA | U39: NA | V39: NA | W39: =IF(ISNUMBER($T39),$T39*$J39*Assumptions!$B$4,"NA") | X39: =IF(ISNUMBER($U39),$U39*$J39*Assumptions!$B$4,"NA") | Y39: =IF(ISNUMBER($V39),$V39*$J39*Assumptions!$B$4,"NA")
A40: Austin Engineering | B40: Dump bodies/truck trays | C40: Hamersley Iron Pty Limited | D40: Owner | E40: Australia | F40: 2025 | G40: 4 | H40: 191254.86 | I40: AUD | J40: =IF($I40="AUD",Assumptions!$B$2,Assumptions!$B$3) | K40: =$G40*$H40*$J40 | L40: =$K40*Assumptions!$B$4 | M40: =RawTx[[#This Row],[Value USD]]/RawTx[[#This Row],[Quantity]] | N40: =RawTx[[#This Row],[Value IDR]]/RawTx[[#This Row],[Quantity]] | O40: YANDICOOGINA-930E-4 HPT STD (177390B) C/W ACCESSORIES PO REFERENCE : 30 | P40: Komatsu | Q40: 930E-4 | R40: 132212 | S40: =IFERROR($R40/$G40,"") | T40: NA | U40: NA | V40: NA | W40: =IF(ISNUMBER($T40),$T40*$J40*Assumptions!$B$4,"NA") | X40: =IF(ISNUMBER($U40),$U40*$J40*Assumptions!$B$4,"NA") | Y40: =IF(ISNUMBER($V40),$V40*$J40*Assumptions!$B$4,"NA")
A41: Austin Engineering | B41: Dump bodies/truck trays | C41: Hamersley Iron Pty Limited | D41: Owner | E41: Australia | F41: 2025 | G41: 1 | H41: 189651.4 | I41: AUD | J41: =IF($I41="AUD",Assumptions!$B$2,Assumptions!$B$3) | K41: =$G41*$H41*$J41 | L41: =$K41*Assumptions!$B$4 | M41: =RawTx[[#This Row],[Value USD]]/RawTx[[#This Row],[Quantity]] | N41: =RawTx[[#This Row],[Value IDR]]/RawTx[[#This Row],[Quantity]] | O41: YANDICOOGINA-830E-AC HPT STD (177391B) C/W ACCESSORIES PO REFERENCE : 3 | P41: Komatsu | Q41: 830E-AC | R41: 27754 | S41: =IFERROR($R41/$G41,"") | T41: NA | U41: NA | V41: NA | W41: =IF(ISNUMBER($T41),$T41*$J41*Assumptions!$B$4,"NA") | X41: =IF(ISNUMBER($U41),$U41*$J41*Assumptions!$B$4,"NA") | Y41: =IF(ISNUMBER($V41),$V41*$J41*Assumptions!$B$4,"NA")
A42: Austin Engineering | B42: Dump bodies/truck trays | C42: Hamersley Iron Pty Limited | D42: Owner | E42: Australia | F42: 2025 | G42: 4 | H42: 189050.53 | I42: AUD | J42: =IF($I42="AUD",Assumptions!$B$2,Assumptions!$B$3) | K42: =$G42*$H42*$J42 | L42: =$K42*Assumptions!$B$4 | M42: =RawTx[[#This Row],[Value USD]]/RawTx[[#This Row],[Quantity]] | N42: =RawTx[[#This Row],[Value IDR]]/RawTx[[#This Row],[Quantity]] | O42: HOPE DOWN 1-830E-5 HPT STD C/W ACCESSORIES PO REFERENCE : 3016364631,3O | P42: Komatsu | Q42: 830E-5 | R42: 113700 | S42: =IFERROR($R42/$G42,"") | T42: 29139.24 | U42: 3046.51 | V42: 1163839 | W42: =IF(ISNUMBER($T42),$T42*$J42*Assumptions!$B$4,"NA") | X42: =IF(ISNUMBER($U42),$U42*$J42*Assumptions!$B$4,"NA") | Y42: =IF(ISNUMBER($V42),$V42*$J42*Assumptions!$B$4,"NA")
...

Sheet Notes
A1: Item | B1: Detail
A2: Structure | B2: Raw Data holds one row per transaction as an Excel table (RawTx) with header filters. Filter any column to isolate exact transactions with their original goods description, brand, model, net weight and customer category.
A3: Buyer name merges | B3: Six buyer names were merged per instruction: Austin Enginnering Limited (2023/2024 rows) to Austin Engineering Limited, Tuprag Metal Madencilik Sanayi ve Tic to Tuprag Metal Madencilik, Gounkoto to Gounkoto SA, HBS Machinery PNG to HBS PNG Limited, Monrobe Consolidated Goldfields to Morobe Consolidated Goldfields Limited, Quad Efficient Engineeringpty Limited to Quad Efficient Engineering Pty Limited, and AST Trading Inc to Advanced Steel Technology.
A4: Two Austin entities | B4: Austin Engineering Limited and Austin Enginnering Limited (double-N) remain separate for 2025 data, as the source platform lists them as distinct importers. Both are classified as Principal (manufacturer/body-builder).
A5: Customer Category | B5: Owner, Contractor, Principal, Trader/Distributor or Fabricator, verified per buyer against public industry sources (company websites, mining news, Wikipedia), not inferred from name alone. See Assumptions for definitions used.
A6: Brand / Type-Model | B6: Extracted from Original Goods Description only where the truck brand and model are explicitly identifiable. Spare parts, tanks, trailers, cyanide sparge tanks and generic hardware are marked NA rather than guessed.
A7: IDR conversion | B7: Value IDR = Value USD x rate in Assumptions!B4 (17,500). Edit that one cell to refresh every sheet, including Raw Data and every pivot's Total IDR column.
A8: Dropped rows | B8: 10 rows with non-integer quantity were removed (Orica Australia / SSB Unit / 2026). 8 rows of 'Komatsu 830 Ultima/Westech Truck Bodies Components' (Austin, Australia, 2023) were removed per instruction.
A9: Every combination shown | B9: P5 Full Matrix lists all categories x competitors including zero-value combinations, so a competitor's absence from a category is a real zero, not a missing row.
A10: P6 new sheet | B10: Customer Category x Competitor shows which competitor sells most to Owners vs Contractors vs Fabricators vs Traders vs Principals.
A11: 2026 | B11: Covers January to September 2026 only.
A12: Formulas | B12: All pivots use live SUMIFS/COUNTIFS against Raw Data. Insert new rows inside the RawTx table and every pivot updates automatically.
